<mujoco model="arm3d">
  <compiler inertiafromgeom="true" angle="radian" coordinate="local"/>
  <option timestep="0.01" gravity="0 0 0" iterations="20" integrator="Euler" />

  <default>
    <joint armature='0.04' damping="1" limited="true"/>
    <geom friction=".8 .1 .1" density="300" margin="0.002" condim="1" contype="0" conaffinity="0"/>
  </default>
  
  <worldbody>
    <light diffuse=".5 .5 .5" pos="0 0 3" dir="0 0 -1"/>
    <geom name="table" type="plane" pos="0 0.5 -0.325" size="1 1 0.1" contype="1" conaffinity="1"/>

    <body name="r_shoulder_pan_link" pos="0 -0.6 0">
      <geom name="e1" type="sphere" rgba="0.6 0.6 0.6 1" pos="-0.06 0.05 0.2" size="0.05" />
      <geom name="e2" type="sphere" rgba="0.6 0.6 0.6 1" pos=" 0.06 0.05 0.2" size="0.05" />
      <geom name="e1p" type="sphere" rgba="0.1 0.1 0.1 1" pos="-0.06 0.09 0.2" size="0.03" />
      <geom name="e2p" type="sphere" rgba="0.1 0.1 0.1 1" pos=" 0.06 0.09 0.2" size="0.03" />
      <geom name="sp" type="capsule" fromto="0 0 -0.4 0 0 0.2" size="0.1" />
    </body>

    <!-- Floating end effector -->
    <body name="r_wrist_roll_link" pos="0 0 0">
      <joint name="ee_x" type="slide" pos="0.1 0 0" limited="true" axis="1 0 0" damping="0.1" range="-0.5 0.5"/>
      <joint name="ee_y" type="slide" pos="0.1 0 0" limited="true" axis="0 1 0" damping="0.1" range="-0.5 0.5"/>
      <joint name="ee_z" type="slide" pos="0.1 0 0" limited="true" axis="0 0 1" damping="0.1" range="-0.3 0.0"/>
      <joint name="ee_wz" type="hinge" pos="0 0 0" limited="true" axis="0 0 1" damping="0.1" range="-1.7 1.7"/>
      <body name="tips_arm" pos="0 0 0">
        <geom name="tip_arml" type="sphere" pos="-0.1 0 0." size="0.01" />
        <geom name="tip_armr" type="sphere" pos=" 0.1 0 0." size="0.01" />
      </body>
      <geom type="capsule" fromto="-0.1 -0.1 0  0.1 -0.1 0" size="0.02" contype="1" conaffinity="1" />
      <geom type="capsule" fromto="-0.1  0   0 -0.1 -0.1 0" size="0.02" contype="1" conaffinity="1" />
      <geom type="capsule" fromto=" 0.1  0   0  0.1 -0.1 0." size="0.02" contype="1" conaffinity="1" />
    </body>

    <body name="object" pos="0.0 0.0 -0.275" >
      <!--geom rgba="0.5 0.5 1 1" type="sphere" size="0.06 0.06" density="0.00001" contype="1" conaffinity="0"/-->
      <geom rgba="0 0 0 0" type="sphere" size="0.05 0.05" density="0.00001" conaffinity="0"/>
      <geom rgba="1 1 1 1" type="cylinder" size="0.05 0.05 0.05" density="0.00001" contype="1" conaffinity="0"/>
      <joint name="obj_slidey" type="slide" pos="0 0 0" axis="0 1 0" range="-10.3213 10.3" damping="0.5"/>
      <joint name="obj_slidex" type="slide" pos="0 0 0" axis="1 0 0" range="-10.3213 10.3" damping="0.5"/>
    </body>

    <body name="goal" pos="0.0 0.0 -0.3230">
      <geom rgba="1 0 0 1" type="cylinder" size="0.08 0.001 0.1" density='0.00001' contype="0" conaffinity="0"/>
      <joint name="goal_slidey" type="slide" pos="0 0 0" axis="0 1 0" range="-10.3213 10.3" damping="0.5"/>
      <joint name="goal_slidex" type="slide" pos="0 0 0" axis="1 0 0" range="-10.3213 10.3" damping="0.5"/> 
    </body>
  </worldbody>

  <actuator>
    <velocity joint="ee_x" ctrlrange="-2.0 2.0" ctrllimited="true"/>
    <velocity joint="ee_y" ctrlrange="-2.0 2.0" ctrllimited="true"/>
    <velocity joint="ee_z" ctrlrange="-2.0 2.0" ctrllimited="true"/>
    <velocity joint="ee_wz" ctrlrange="-2.0 2.0" ctrllimited="true"/>
  </actuator>
</mujoco>
